Workbook
Name Inventory: Inventory!$A$3:$H$50
Name Survey: 'Satisfaction Survey'!$A$4:$G$40

Sheet Satisfaction Survey
A1: WearEver Shoes and Accessories
A2: Customer Experience Survey Results
A4: Order ID | B4: Product | C4: Color | D4: Size | E4: Comfort | F4: Fit | G4: Style
A5: WE001 | B5: Rugged Hiking Boots | C5: Brown | D5: 8 | E5: 7 | F5: 9 | G5: 7
A6: WE002 | B6: Rugged Hiking Boots | C6: Brown | D6: 10 | E6: 8 | F6: 8 | G6: 10
A7: WE003 | B7: Rugged Hiking Boots | C7: Black | D7: 9.5 | E7: 8 | F7: 9 | G7: 8
A8: WE004 | B8: Rugged Hiking Boots | C8: Black | D8: 10.5 | E8: 6 | F8: 9 | G8: 9
A9: WE005 | B9: Rugged Hiking Boots | C9: Black | D9: 7.5 | E9: 8 | F9: 8 | G9: 10
A10: WE006 | B10: Rugged Hiking Boots | C10: Black | D10: 8 | E10: 7 | F10: 9 | G10: 9
A11: WE007 | B11: Rugged Hiking Boots | C11: Brown | D11: 9 | E11: 9 | F11: 9 | G11: 8
A12: WE008 | B12: Rugged Hiking Boots | C12: Brown | D12: 8.5 | E12: 9 | F12: 8 | G12: 9
A13: WE009 | B13: Comfy Walking Shoes | C13: Brown | D13: 8.5 | E13: 8 | F13: 3 | G13: 8
A14: WE010 | B14: Comfy Walking Shoes | C14: Black | D14: 9 | E14: 10 | F14: 10 | G14: 8
A15: WE011 | B15: Comfy Walking Shoes | C15: Navy | D15: 7.5 | E15: 9 | F15: 3 | G15: 8
A16: WE012 | B16: Comfy Walking Shoes | C16: Black | D16: 8 | E16: 7 | F16: 5 | G16: 10
... A40: WE036 | B40: Glide Running Shoes | C40: Black | D40: 10 | E40: 10 | F40: 10 | G40: 9

Sheet Average Ratings
A1: WearEver Shoes and Accessories
A2: Average Ratings by Shoe Style
A4: Product | B4: Comfort | C4: Fit | D4: Style | E4: Overall | F4: Rating | H4: Ratings
A5: Rugged Hiking Boots | B5: =DAVERAGE(Survey,B$4,Criteria!$A$1:$A$2) -> 7.75 | C5: =DAVERAGE(Survey,C$4,Criteria!$A$1:$A$2) -> 8.625 | D5: =DAVERAGE(Survey,D$4,Criteria!$A$1:$A$2) -> 8.75 | E5: =AVERAGE(B5:D5) -> 8.375 | F5: {=_xlfn.IFS(E5>=9,$H$5,E5>=8,$H$6,E5>=5,$H$7,E5<5,$H$8)} -> Above Average | H5: Excellent | I5: >=9
A6: Comfy Walking Shoes | B6: =DAVERAGE(Survey,B$4,Criteria!$A$4:$A$5) -> 7.5 | C6: =DAVERAGE(Survey,C$4,Criteria!$A$4:$A$5) -> 5.3333333 | D6: =DAVERAGE(Survey,D$4,Criteria!$A$4:$A$5) -> 7.5 | E6: =AVERAGE(B6:D6) -> 6.7777778 | F6: {=_xlfn.IFS(E6>=9,$H$5,E6>=8,$H$6,E6>=5,$H$7,E6<5,$H$8)} -> Average | H6: Above Average | I6: Between 8 and 9
A7: Lazy Flip-Flops | B7: =DAVERAGE(Survey,B$4,Criteria!$A$7:$A$8) -> 4.9 | C7: =DAVERAGE(Survey,C$4,Criteria!$A$7:$A$8) -> 3.3 | D7: =DAVERAGE(Survey,D$4,Criteria!$A$7:$A$8) -> 5.5 | E7: =AVERAGE(B7:D7) -> 4.5666667 | F7: {=_xlfn.IFS(E7>=9,$H$5,E7>=8,$H$6,E7>=5,$H$7,E7<5,$H$8)} -> Poor | H7: Average | I7: Between 5 and 7
A8: Seriously Tall Boots | B8: =DAVERAGE(Survey,B$4,Criteria!$A$10:$A$11) -> 6.6666667 | C8: =DAVERAGE(Survey,C$4,Criteria!$A$10:$A$11) -> 5 | D8: =DAVERAGE(Survey,D$4,Criteria!$A$10:$A$11) -> 6.5 | E8: =AVERAGE(B8:D8) -> 6.0555556 | F8: {=_xlfn.IFS(E8>=9,$H$5,E8>=8,$H$6,E8>=5,$H$7,E8<5,$H$8)} -> Average | H8: Poor | I8: <5
A9: Glide Running Shoes | B9: =DAVERAGE(Survey,B$4,Criteria!$A$13:$A$14) -> 9.1666667 | C9: =DAVERAGE(Survey,C$4,Criteria!$A$13:$A$14) -> 9.5 | D9: =DAVERAGE(Survey,D$4,Criteria!$A$13:$A$14) -> 8.8333333 | E9: =AVERAGE(B9:D9) -> 9.1666667 | F9: {=_xlfn.IFS(E9>=9,$H$5,E9>=8,$H$6,E9>=5,$H$7,E9<5,$H$8)} -> Excellent

Sheet Criteria
A1: Product | B1: Color | C1: Size | D1: Quantity
A2: rug*
A4: Product | B4: Color | C4: Size | D4: Quantity
A5: com*
A7: Product | B7: Color | C7: Size | D7: Quantity
A8: laz*
A10: Product | B10: Color | C10: Size | D10: Quantity
A11: ser*
A13: Product | B13: Color | C13: Size | D13: Quantity
A14: gli*

Sheet Shipment Times
A1: WearEver Shoes and Accessories
A2: Shipment Times
A4: Order # | B4: Shipped | C4: Arrived | D4: Days | E4: Arrival Day
A5: WESA001 | B5: =TODAY() -> 45400 | C5: =B5+4 -> 45404 | D5: =C5-B5 -> 4 | E5: =TEXT(C5,"dddd") -> Monday
A6: WESA002 | B6: =B5+2 -> 45402 | C6: =B6+3 -> 45405 | D6: =C6-B6 -> 3 | E6: =TEXT(C6,"dddd") -> Tuesday
A7: WESA003 | B7: =TODAY() -> 45400 | C7: =B7+6 -> 45406 | D7: =C7-B7 -> 6 | E7: =TEXT(C7,"dddd") -> Wednesday
A8: WESA004 | B8: =B7+2 -> 45402 | C8: =B8+4 -> 45406 | D8: =C8-B8 -> 4 | E8: =TEXT(C8,"dddd") -> Wednesday
A9: WESA005 | B9: =TODAY() -> 45400 | C9: =B9+3 -> 45403 | D9: =C9-B9 -> 3 | E9: =TEXT(C9,"dddd") -> Sunday
A10: WESA006 | B10: =B9+2 -> 45402 | C10: =B10+7 -> 45409 | D10: =C10-B10 -> 7 | E10: =TEXT(C10,"dddd") -> Saturday
A11: WESA007 | B11: =TODAY() -> 45400 | C11: =B11+3 -> 45403 | D11: =C11-B11 -> 3 | E11: =TEXT(C11,"dddd") -> Sunday
A12: WESA008 | B12: =B11+2 -> 45402 | C12: =B12+6 -> 45408 | D12: =C12-B12 -> 6 | E12: =TEXT(C12,"dddd") -> Friday
A13: WESA009 | B13: =TODAY() -> 45400 | C13: =B13+3 -> 45403 | D13: =C13-B13 -> 3 | E13: =TEXT(C13,"dddd") -> Sunday
A14: WESA010 | B14: =B13+2 -> 45402 | C14: =B14+6 -> 45408 | D14: =C14-B14 -> 6 | E14: =TEXT(C14,"dddd") -> Friday
A15: WESA011 | B15: =TODAY() -> 45400 | C15: =B15+4 -> 45404 | D15: =C15-B15 -> 4 | E15: =TEXT(C15,"dddd") -> Monday
A16: WESA012 | B16: =B15+2 -> 45402 | C16: =B16+3 -> 45405 | D16: =C16-B16 -> 3 | E16: =TEXT(C16,"dddd") -> Tuesday
A17: WESA013 | B17: =TODAY() -> 45400 | C17: =B17+5 -> 45405 | D17: =C17-B17 -> 5 | E17: =TEXT(C17,"dddd") -> Tuesday
A18: WESA014 | B18: =B17+2 -> 45402 | C18: =B18+6 -> 45408 | D18: =C18-B18 -> 6 | E18: =TEXT(C18,"dddd") -> Friday
A19: WESA015 | B19: =TODAY() -> 45400 | C19: =B19+2 -> 45402 | D19: =C19-B19 -> 2 | E19: =TEXT(C19,"dddd") -> Saturday
A20: WESA016 | B20: =B19+2 -> 45402 | C20: =B20+5 -> 45407 | D20: =C20-B20 -> 5 | E20: =TEXT(C20,"dddd") -> Thursday
A21: WESA017 | B21: =TODAY() -> 45400 | C21: =B21+3 -> 45403 | D21: =C21-B21 -> 3 | E21: =TEXT(C21,"dddd") -> Sunday
A22: WESA018 | B22: =B21+2 -> 45402 | C22: =B22+3 -> 45405 | D22: =C22-B22 -> 3 | E22: =TEXT(C22,"dddd") -> Tuesday
A23: WESA019 | B23: =TODAY() -> 45400 | C23: =B23+5 -> 45405 | D23: =C23-B23 -> 5 | E23: =TEXT(C23,"dddd") -> Tuesday
A24: WESA020 | B24: =B23+2 -> 45402 | C24: =B24+7 -> 45409 | D24: =C24-B24 -> 7 | E24: =TEXT(C24,"dddd") -> Saturday
A25: WESA021 | B25: =TODAY() -> 45400 | C25: =B25+6 -> 45406 | D25: =C25-B25 -> 6 | E25: =TEXT(C25,"dddd") -> Wednesday
A26: WESA022 | B26: =B25+2 -> 45402 | C26: =B26+5 -> 45407 | D26: =C26-B26 -> 5 | E26: =TEXT(C26,"dddd") -> Thursday
A27: WESA023 | B27: =TODAY() -> 45400 | C27: =B27+5 -> 45405 | D27: =C27-B27 -> 5 | E27: =TEXT(C27,"dddd") -> Tuesday
A28: WESA024 | B28: =B27+2 -> 45402 | C28: =B28+7 -> 45409 | D28: =C28-B28 -> 7 | E28: =TEXT(C28,"dddd") -> Saturday
A29: WESA025 | B29: =TODAY() -> 45400 | C29: =B29+5 -> 45405 | D29: =C29-B29 -> 5 | E29: =TEXT(C29,"dddd") -> Tuesday
A30: WESA026 | B30: =B29+2 -> 45402 | C30: =B30+4 -> 45406 | D30: =C30-B30 -> 4 | E30: =TEXT(C30,"dddd") -> Wednesday
A31: WESA027 | B31: =TODAY() -> 45400 | C31: =B31+6 -> 45406 | D31: =C31-B31 -> 6 | E31: =TEXT(C31,"dddd") -> Wednesday
A32: WESA028 | B32: =B31+2 -> 45402 | C32: =B32+7 -> 45409 | D32: =C32-B32 -> 7 | E32: =TEXT(C32,"dddd") -> Saturday
A33: WESA029 | B33: =TODAY() -> 45400 | C33: =B33+7 -> 45407 | D33: =C33-B33 -> 7 | E33: =TEXT(C33,"dddd") -> Thursday
A34: WESA030 | B34: =B33+2 -> 45402 | C34: =B34+6 -> 45408 | D34: =C34-B34 -> 6 | E34: =TEXT(C34,"dddd") -> Friday
A35: WESA031 | B35: =TODAY() -> 45400 | C35: =B35+3 -> 45403 | D35: =C35-B35 -> 3 | E35: =TEXT(C35,"dddd") -> Sunday
A36: WESA032 | B36: =B35+2 -> 45402 | C36: =B36+6 -> 45408 | D36: =C36-B36 -> 6 | E36: =TEXT(C36,"dddd") -> Friday
A37: WESA033 | B37: =TODAY() -> 45400 | C37: =B37+2 -> 45402 | D37: =C37-B37 -> 2 | E37: =TEXT(C37,"dddd") -> Saturday
A38: WESA034 | B38: =B37+2 -> 45402 | C38: =B38+2 -> 45404 | D38: =C38-B38 -> 2 | E38: =TEXT(C38,"dddd") -> Monday
A39: WESA035 | B39: =TODAY() -> 45400 | C39: =B39+6 -> 45406 | D39: =C39-B39 -> 6 | E39: =TEXT(C39,"dddd") -> Wednesday
A40: WESA036 | B40: =B39+2 -> 45402 | C40: =B40+7 -> 45409 | D40: =C40-B40 -> 7 | E40: =TEXT(C40,"dddd") -> Saturday

Sheet Inventory
A1: WearEver Accessories Inventory
A2: 45930
A3: Product ID | B3: Product | C3: Color | D3: Size | E3: Quantity | F3: Men's or Women's | G3: Cost | H3: Retail
A4: WE040 | B4: AllAround Shoulder Bag | C4: Tan | E4: 4 | G4: 65 | H4: 85
A5: WE041 | B5: AllAround Shoulder Bag | C5: Black | E5: 3 | G5: 65 | H5: 85 | J5: Product ID | K5: WE040
A6: WE037 | B6: Chunky Heel Boots | C6: Black | D6: 7.5 | E6: 4 | F6: W | G6: 55 | H6: 70 | J6: Quantity | K6: {=INDEX(Inventory,_xlfn.XMATCH(K5,A3:A50),_xlfn.XMATCH("quantity",A3:H3))} -> 4
A7: WE038 | B7: Chunky Heel Boots | C7: Black | D7: 8.5 | E7: 3 | F7: W | G7: 55 | H7: 70
A8: WE039 | B8: Chunky Heel Boots | C8: Brown | D8: 8 | E8: 6 | F8: W | G8: 55 | H8: 70
A9: WE009 | B9: Comfy Walking Shoes | C9: Brown | D9: 8.5 | E9: 4 | F9: M | G9: 47.5 | H9: 65
A10: WE010 | B10: Comfy Walking Shoes | C10: Black | D10: 9 | E10: 1 | F10: M | G10: 47.5 | H10: 65
A11: WE011 | B11: Comfy Walking Shoes | C11: Navy | D11: 7.5 | E11: 4 | F11: W | G11: 47.5 | H11: 65 | J11: Specific Product Counts
A12: WE012 | B12: Comfy Walking Shoes | C12: Black | D12: 8 | E12: 1 | F12: W | G12: 47.5 | H12: 65 | J12: Product | K12: Color | L12: In Stock
A13: WE013 | B13: Comfy Walking Shoes | C13: Taupe | D13: 7.5 | E13: 2 | F13: W | G13: 47.5 | H13: 65 | J13: Rugged Hiking Boots | K13: Black | L13: =SUMIFS($E$4:$E$50,$C$4:$C$50,K13,$B$4:$B$50,J13) -> 16
A14: WE014 | B14: Comfy Walking Shoes | C14: Brown | D14: 8 | E14: 3 | F14: W | G14: 47.5 | H14: 65 | J14: Glide Running Shoes | K14: White | L14: =SUMIFS($E$4:$E$50,$C$4:$C$50,K14,$B$4:$B$50,J14) -> 18
A15: WE042 | B15: Cool Crossbuddy | C15: Multi | E15: 3 | G15: 50 | H15: 60
A16: WE031 | B16: Glide Running Shoes | C16: White | D16: 8 | E16: 6 | F16: M | G16: 48 | H16: 75 | J16: Handbag Products | L16: =SUMIFS(E4:E50,D4:D50,"=",F4:F50,"=") -> 26
A17: WE032 | B17: Glide Running Shoes | C17: White | D17: 9 | E17: 6 | F17: M | G17: 48 | H17: 75
A18: WE033 | B18: Glide Running Shoes | C18: White | D18: 10 | E18: 6 | F18: M | G18: 48 | H18: 75
A19: WE034 | B19: Glide Running Shoes | C19: Black | D19: 8 | E19: 2 | F19: M | G19: 48 | H19: 75
A20: WE035 | B20: Glide Running Shoes | C20: Black | D20: 9 | E20: 3 | F20: M | G20: 48 | H20: 75
A21: WE036 | B21: Glide Running Shoes | C21: Black | D21: 10 | E21: 1 | F21: M | G21: 48 | H21: 75
A22: WE043 | B22: Greenlee Satchel | C22: Multi | E22: 5 | G22: 70 | H22: 85
A23: WE015 | B23: Lazy Flip-Flops | C23: Pink | D23: 6 | E23: 4 | F23: W | G23: 7.5 | H23: 14
A24: WE016 | B24: Lazy Flip-Flops | C24: Pink | D24: 7 | E24: 0 | F24: W | G24: 7.5 | H24: 14
A25: WE017 | B25: Lazy Flip-Flops | C25: Pink | D25: 8 | E25: 2 | F25: W | G25: 7.5 | H25: 14
A26: WE018 | B26: Lazy Flip-Flops | C26: White | D26: 6 | E26: 3 | F26: W | G26: 7.5 | H26: 14
A27: WE019 | B27: Lazy Flip-Flops | C27: White | D27: 7 | E27: 1 | F27: W | G27: 7.5 | H27: 14
A28: WE020 | B28: Lazy Flip-Flops | C28: White | D28: 8 | E28: 2 | F28: W | G28: 7.5 | H28: 14
A29: WE021 | B29: Lazy Flip-Flops | C29: Brown | D29: 8 | E29: 2 | F29: M | G29: 7.5 | H29: 14
A30: WE022 | B30: Lazy Flip-Flops | C30: Brown | D30: 9 | E30: 4 | F30: M | G30: 7.5 | H30: 14
A31: WE023 | B31: Lazy Flip-Flops | C31: Brown | D31: 10 | E31: 2 | F31: M | G31: 7.5 | H31: 14
A32: WE024 | B32: Lazy Flip-Flops | C32: Brown | D32: 11 | E32: 2 | F32: M | G32: 7.5 | H32: 14
A33: WE044 | B33: Monroe Tote | C33: Ivory | E33: 2 | G33: 65 | H33: 80
A34: WE045 | B34: Monroe Tote | C34: Red | E34: 3 | G34: 65 | H34: 80
A35: WE046 | B35: Nightfall Clutch | C35: Brown | E35: 2 | G35: 45 | H35: 55
A36: WE047 | B36: Nightfall Clutch | C36: Pewter | E36: 4 | G36: 45 | H36: 55
A37: WE001 | B37: Rugged Hiking Boots | C37: Brown | D37: 8 | E37: 5 | F37: M | G37: 46.5 | H37: 90
A38: WE002 | B38: Rugged Hiking Boots | C38: Brown | D38: 10 | E38: 3 | F38: M | G38: 46.5 | H38: 90
A39: WE003 | B39: Rugged Hiking Boots | C39: Black | D39: 9.5 | E39: 6 | F39: M | G39: 46.5 | H39: 90
A40: WE004 | B40: Rugged Hiking Boots | C40: Black | D40: 10.5 | E40: 4 | F40: M | G40: 46.5 | H40: 90
...

Sheet E-Mail
A1: Wear-Ever Shoes
A2: Employee E-Mail List
A4: First Name | B4: Last Name | C4: Email Addresses
A5: Vincent | B5: Bowman
A6: Louis | B6: White
A7: Patricia | B7: Lynwood
A8: Drew | B8: Cronin
